Workbook

Sheet Elementos fisicos
B2: Nombre del componente | C2: Especificaciones | D2: Cantidad | E2: P.U. Económico | F2: P.U Medio | G2: P.U. Full | H2: Total Eco | I2: Total Medio | J2: Total Full | K2: Img. de ref. eco | L2: Img. de ref. med | M2: Img. de ref. full
B3: Servidor físico (Rack o Torre) | C3: Opción Económica: Servidor HP ML30 Gen10 Plus con procesador Intel Xeon E-2314 (4 núcleos), 16GB de RAM, y configuración de almacenamiento de 2 discos de 1TB en RAID 1. Opción Media: Servidor HP ML30 Gen10 Plus con procesador Intel Xeon E-2336 (6 núcleos), 32GB de RAM, y 2 discos de 4TB en RAID 1. Opción Full: Servidor HP ML30 Gen10 Plus con procesador Intel Xeon E-2336 (6 núcleos), 64GB de RAM, y 4 discos de 4TB configurados en RAID 10 para máxima velocidad y redundancia. | D3: 1 | E3: 3359600 | F3: 13420000 | G3: 35985000 | H3: =SUM(D3*E3) -> 3359600 | I3: =SUM(D3*F3) -> 13420000 | J3: =D3*G3 -> 35985000
B4: PC | C4: Opción Económica: PC de oficina básico con procesador Core i3 / Ryzen 3, 8GB RAM, 256GB SSD y monitor de 21". Opción Media: PC estándar con procesador Core i5 / Ryzen 5, 16GB RAM, 512GB SSD y monitor de 24" Full HD. Opción Full: PC de alto rendimiento con procesador Core i7 / Ryzen 7, 32GB RAM, 1TB NVMe SSD y monitor de 27" (posiblemente 4K). | D4: 1 | E4: 3680000 | F4: 4666000 | G4: 31200000 | H4: =D4*E4 -> 3680000 | I4: =D4*F4 -> 4666000 | J4: =D4*G4 -> 31200000
B5: Portatil | C5: Opción Económica: Portátil básico con Core i3 / Ryzen 3, 8GB RAM, 256GB SSD y pantalla HD. Opción Media: Portátil de trabajo con Core i5 / Ryzen 5, 16GB RAM, 512GB SSD y pantalla Full HD con chasis mejorado. Opción Full: Portátil Premium/Pro con Core i7 / Ryzen 7, 32GB RAM, 1TB NVMe SSD, pantalla de alta calidad (4K/OLED) y GPU dedicada. | D5: 1 | E5: 2100000 | F5: 8600000 | G5: 24200000 | H5: =D5*E5 -> 2100000 | I5: =D5*F5 -> 8600000 | J5: =D5*G5 -> 24200000
B6: UPS industrial | C6: Opción Económica: El UPS tiene una capacidad de 2 KVA / 1.8 kW y utiliza tecnología Básica (Línea Interactiva o Doble Conversión). Ofrece una autonomía mínima de 5 a 10 minutos, suficiente para el apagado seguro de los equipos, y su conectividad es a través de puertos USB y Serie. Opción Media: El UPS aumenta su capacidad a 3 KVA / 2.7 kW y utiliza tecnología Doble Conversión (Online) de Alta Eficiencia, garantizando energía limpia. Proporciona una autonomía adecuada de 15 a 20 minutos y se gestiona mediante una Tarjeta SNMP para el monitoreo remoto avanzado a través de la red. Opción Full: El UPS de alto rendimiento tiene una capacidad de 5 KVA / 4.5 kW (o más) con tecnología Doble Conversión (Online) de máxima eficiencia y alto factor de potencia (cercano a 1). Ofrece una autonomía extendida de 30 a 45 minutos o mediante Módulos de Batería Externa. La gestión es premium, con Tarjeta SNMP redundante y Software de Gestión Centralizada. | D6: 1 | E6: 940000 | F6: 2399900 | G6: 4417900 | H6: =D6*E6 -> 940000 | I6: =D6*F6 -> 2399900 | J6: =D6*G6 -> 4417900
B7: Gabinete Rack 42U | C7: Opción Económica: Gabinete Rack 42U de profundidad estándar (aproximadamente 800-1000 mm). Incluye cerraduras básicas y ventilación pasiva. Es adecuado para un entorno de rack simple que solo aloja el equipo mínimo (Servidor Económico, UPS y Switch). Opción Media: Gabinete Rack 42U de profundidad optimizada (1000-1200 mm) para mejor gestión de cableado y flujo de aire. Incluye paneles laterales removibles con llave y una o dos unidades de ventilación (fans) montadas en el techo. Ofrece una construcción más robusta y mejor manejo térmico para el equipo estándar. Opción Full: Gabinete Rack 42U de máxima profundidad y resistencia, con alta capacidad de peso. Incluye acceso de seguridad avanzado (posiblemente biométrico o cerraduras de múltiples puntos), sistema de ventilación activa (múltiples fans de alta eficiencia) y gestión de cableado vertical de alta densidad. Diseñado para alojar una alta concentración de equipos (Servidor Full, UPS grande, etc.) y maximizar la eficiencia térmica. | D7: 1 | E7: 1065823 | F7: 3291319 | G7: 5713663 | H7: =D7*E7 -> 1065823 | I7: =D7*F7 -> 3291319 | J7: =D7*G7 -> 5713663
B8: Switch administrable 24 puertos | C8: Opción Económica: TP-LINK 8 Puertos (Gigabit, No Gestionable), adecuado para una oficina pequeña. Opción Media: TP-LINK 16 Puertos (Gigabit, No Gestionable), estándar para una red en crecimiento. Opción Full: TP-LINK 24 Puertos (Gigabit, No Gestionable), para alta densidad de conexiones. | D8: 1 | E8: 460107 | F8: 1093093 | G8: 1708900 | H8: =D8*E8 -> 460107 | I8: =D8*F8 -> 1093093 | J8: =D8*G8 -> 1708900
B9: Router empresarial con firewall | C9: Opción Económica: Router/Firewall de Gama Baja (ej. entrada FortiGate o pfSense en hardware simple). Ofrece VPN básica (limitado a 5-10 usuarios) y protección simple de cortafuegos de estado (stateful). Ideal para conexiones de internet de hasta 100 Mbps. Opción Media: Router/Firewall de Gama Media (ej. FortiGate 60F o similar). Ofrece alto rendimiento en VPN (hasta 25 usuarios), filtrado web y antivirus en el gateway. Velocidad de rendimiento (throughput) garantizada de hasta 500 Mbps. Opción Full: Router/Firewall de Gama Alta (ej. FortiGate 100F o superior). Capacidad de alto rendimiento y redundancia (HA), con funciones avanzadas (UTM/SD-WAN), IPS/IDS y alta capacidad de VPN (50+ usuarios). Diseñado para conexiones de 1 Gbps o más. | D9: 1 | E9: 809978 | F9: 4629112 | G9: 17567285 | H9: =D9*E9 -> 809978 | I9: =D9*F9 -> 4629112 | J9: =D9*G9 -> 17567285
B10: Cableado estructurado Cat6 | C10: Opción Económica: Instalación con cable Cat6 básico y canalización sencilla. Incluye patch panels y tomas de red genéricos. Enfocado en la funcionalidad mínima y cumplimiento de estándares para velocidad de 1 Gbps. Opción Media: Instalación con cable Cat6 de marca reconocida, con certificación de calidad y una gestión de cableado profesional (orden y etiquetado). Utiliza patch panels y conectores de alta calidad. Rendimiento confiable de 1 Gbps con buena inmunidad a interferencias. Opción Full: Instalación con cable Cat6A (que es la evolución de Cat6 para mayores distancias/ancho de banda) o Cat6 Premium blindado (Shielded). Incluye bandejas de cableado, gestión vertical/horizontal avanzada, y certificación de rendimiento de 10 Gbps para el futuro. | D10: 1 | E10: 185000 | F10: 4353000 | G10: 8144710 | H10: =D10*E10 -> 185000 | I10: =D10*F10 -> 4353000 | J10: =D10*G10 -> 8144710
B11: Aire acondicionado para rack | C11: Opción Económica: Sistema de enfriamiento Portátil/Mini-Split simple (no dedicado al rack) o Extracción de Aire caliente (fan de techo/alto flujo). Se basa en la climatización general de la sala, con una capacidad de 5,000 - 8,000 BTUs. Opción Media: Unidad de Aire Acondicionado Mini-Split Inverter de Alta Eficiencia con capacidad de 9,000 - 12,000 BTUs. Montaje tipo pared. Ideal para mantener una temperatura controlada en una sala pequeña de servidores con equipos estándar. Opción Full: Sistema de enfriamiento de precisión (CRAC) o Unidad de Aire Acondicionado de Rack Fila (In-Row Cooling). Capacidad de 15,000 BTUs o superior. Diseñado para un enfriamiento dedicado y continuo, con monitoreo de humedad y temperatura 24/7. Es esencial para el Servidor Full y el Gabinete Rack de alta densidad. | D11: 1 | E11: 2900000 | F11: 3800000 | G11: 10237500 | H11: =D11*E11 -> 2900000 | I11: =D11*F11 -> 3800000 | J11: =D11*G11 -> 10237500
B12: Panel de parches 24 puertos | C12: Opción Económica: Panel de parches Cat6 sin blindaje (UTP), de marca genérica, con terminación simple y estándar. Cumple la función básica de interconexión. Opción Media: Panel de parches Cat6 de marca reconocida, robusto, con mejor soporte de gestión de cableado en la parte trasera. Asegura una conectividad confiable. Opción Full: Panel de parches Cat6A (preparado para 10 Gbps) o Cat6 Blindado (STP). Diseño de alta densidad o en ángulo para maximizar el espacio y la eficiencia del cableado. | D12: 1 | E12: 100000 | F12: 154900 | G12: 409929 | H12: =D12*E12 -> 100000 | I12: =D12*F12 -> 154900 | J12: =D12*G12 -> 409929

Sheet Servidor Local Princip
B2: Servidor Local Principal
B3: Ítem | C3: Económico (COP) | D3: Medio (COP) | E3: Full (COP) | F3: Comentario
B4: Hardware
B5: Servidor físico (Rack o Torre) | C5: ='Elementos fisicos'!H3 -> 3359600 | D5: ='Elementos fisicos'!I3 -> 13420000 | E5: ='Elementos fisicos'!J3 -> 35985000 | F5: Económico: torre básica, Medio: rack ventilado, Full: rack redundante y profesional
B6: PC mesa | C6: ='Elementos fisicos'!H4 -> 3680000 | D6: ='Elementos fisicos'!I4 -> 4666000 | E6: ='Elementos fisicos'!J4 -> 31200000 | F6: Económico: con coponentes adecuados para la programacion , Medio:ventaja de mejor componentes, Full: redundante y profesional
B7: Portatiles | C7: ='Elementos fisicos'!H5 -> 2100000 | D7: ='Elementos fisicos'!I5 -> 8600000 | E7: ='Elementos fisicos'!J5 -> 24200000 | F7: Económico: con coponentes adecuados para la programacion , Medio:ventaja de mejor componentes, Full: redundante y profesional
B8: UPS industrial 3000 VA | C8: ='Elementos fisicos'!H6 -> 940000 | D8: ='Elementos fisicos'!I6 -> 2399900 | E8: ='Elementos fisicos'!J6 -> 4417900 | F8: Económico: respaldo básico, Medio: tiempo para shutdown, Full: respaldo prolongado + monitoreo
B9: Gabinete Rack 42U | C9: ='Elementos fisicos'!H7 -> 1065823 | D9: ='Elementos fisicos'!I7 -> 3291319 | E9: ='Elementos fisicos'!J7 -> 5713663 | F9: Económico: metálico simple, Medio: ventilado, Full: con gestión de cables y seguridad
B10: Switch administrable 24 puertos | C10: ='Elementos fisicos'!H8 -> 460107 | D10: ='Elementos fisicos'!I8 -> 1093093 | E10: ='Elementos fisicos'!J8 -> 1708900 | F10: Económico: pocos puertos, Medio: gestionable, Full: con PoE y alta capacidad
B11: Router empresarial con firewall | C11: ='Elementos fisicos'!H9 -> 809978 | D11: ='Elementos fisicos'!I9 -> 4629112 | E11: ='Elementos fisicos'!J9 -> 17567285 | F11: Económico: básico, Medio: rendimiento adecuado, Full: alta seguridad y rendimiento
B12: Cableado estructurado Cat6 | C12: ='Elementos fisicos'!H10 -> 185000 | D12: ='Elementos fisicos'!I10 -> 4353000 | E12: ='Elementos fisicos'!J10 -> 8144710 | F12: Económico: cable básico, Medio: con canalización, Full: cableado óptimo + patch panels
B13: Aire acondicionado para rack | C13: ='Elementos fisicos'!H11 -> 2900000 | D13: ='Elementos fisicos'!I11 -> 3800000 | E13: ='Elementos fisicos'!J11 -> 10237500 | F13: Económico: ventilador, Medio: mini split, Full: A/C redundante
B14: Panel de parches 24 puertos | C14: ='Elementos fisicos'!H12 -> 100000 | D14: ='Elementos fisicos'!I12 -> 154900 | E14: ='Elementos fisicos'!J12 -> 409929 | F14: Económico: simple, Medio: más puertos, Full: con gestión y etiquetado
B15: total de costo Hardware | C15: =SUM(C5:C14) -> 15600508 | D15: =SUM(D5:D14) -> 46407324 | E15: =SUM(E5:E14) -> 139584887
B16: Software
B17: Sistema operativo Linux | C17: 0 | D17: 0 | E17: 843946.43 | F17: Económico: gratis, Medio: estable, Full: con soporte empresarial
B18: Windows Server | C18: 546000 | D18: 8190000 | E18: 16200000 | F18: Económico: licencia básica, 10 usu, Medio: con CALs , max 30 usu Full: Datacenter, 50+ usu
B19: Servidor web Nginx | C19: 250000 | D19: 550000 | E19: 1400000 | F19: Económico: estándar, Medio: con balanceo, Full: configurado para alta carga
B20: Base de datos PostgreSQL | C20: 300000 | D20: 750000 | E20: 4000000 | F20: Económico: versión comunitaria, Medio: con soporte, Full: clúster HA
B21: Firewall software (pfSense) | C21: 300000 | D21: 800000 | E21: 2500000 | F21: Económico: configuración básica, Medio: rutas avanzadas, Full: IDS/IPS + VPN
B22: Administración remota (SSH) | C22: 150000 | D22: 350000 | E22: 900000 | F22: Siempre presente, seguro para todos los entornos
B23: Antivirus Corporativo | C23: 500000 | D23: 1500000 | E23: 4000000 | F23: Económico: versión ligera, Medio: protección completa, Full: con sandbox y control avanzado
B24: Sistema de backups local | C24: 350000 | D24: 800000 | E24: 2500000 | F24: Económico: script manual, Medio: automatico, Full: incremental + encriptado
B25: Monitoreo (Zabbix) | C25: 500000 | D25: 1600000 | E25: 4500000 | F25: Económico: host básico, Medio: alertas, Full: dashboard + informes
B26: Logs centralizados (ELK) | C26: 500000 | D26: 2000000 | E26: 4200000 | F26: Económico: logs simples, Medio: visualización, Full: cluster y alertas
B27: total de costo Software | C27: =SUM(C17:C26) -> 3396000 | D27: =SUM(D17:D26) -> 16540000 | E27: =SUM(E17:E26) -> 41043946
B28: Configuración
B29: Instalación servidor físico | C29: 890000 | D29: 1600000 | E29: 3200000 | F29: Económico: instalación rígida, Medio: con pruebas, Full: redundancia y hardening
B30: Configuración de red interna | C30: 450000 | D30: 1400000 | E30: 3500000 | F30: Económico: red simple, Medio: VLANs, Full: segmentación + QoS
B31: Seguridad del servidor | C31: 350000 | D31: 900000 | E31: 2200000 | F31: Económico: firewall básico, Medio: reglas + IDS, Full: auditoría + pentesting
B32: RAID almacenamiento | C32: 300000 | D32: 650000 | E32: 1400000 | F32: Económico: RAID1, Medio: RAID5, Full: RAID10 con cache
B33: Instalación servicios web | C33: 250000 | D33: 750000 | E33: 1600000 | F33: Económico: solo Nginx, Medio: Nginx + apps, Full: autoscaling
B34: Configuración base de datos | C34: 200000 | D34: 800000 | E34: 2200000 | F34: Económico: instancia única, Medio: backup, Full: replicación y HA
B35: Roles y usuarios | C35: 150000 | D35: 500000 | E35: 1200000 | F35: Económico: pocos roles, Medio: roles definidos, Full: control granular y auditoría
B36: VPN acceso remoto | C36: 200000 | D36: 700000 | E36: 1800000 | F36: Económico: OpenVPN básico, Medio: certificados, Full: MFA + redundancia
B37: Pruebas internas del servidor | C37: 100000 | D37: 500000 | E37: 1500000 | F37: Económico: pruebas mínimas, Medio: carga, Full: simulación completa
B38: total de costos de Configuración | C38: =SUM(C29:C37) -> 2890000 | D38: =SUM(D29:D37) -> 7800000 | E38: =SUM(E29:E37) -> 18600000
B39: Costos operativos
B40: Consumo energético año | C40: 1200000 | D40: 3600000 | E40: 6000000 | F40: Económico: estimación, Medio: medición, Full: monitoreo y optimización
B41: Mantenimiento preventivo anual | C41: 400000 | D41: 1000000 | E41: 2500000 | F41: Económico: revisión básica, Medio: completo, Full: reemplazo proactivo
...

Sheet Servidor Externo _ Clo
B2: Servidor Externo / Cloud
B3: Ítem | C3: Económico (COP) | D3: Medio (COP) | E3: Full (COP) | F3: Comentario
B4: Infraestructura cloud Amazon Web Services (AWS)
B5: Instancia VPS Cloud 4 CPU / 8GB RAM | C5: 600000 | D5: 1500000 | E5: 3000000 | F5: Económico: VPS básico, Medio: rendimiento balanceado, Full: VPS potenciado
B6: Instancia Cloud con 8 CPU / 16GB RAM | C6: 1200000 | D6: 3000000 | E6: 7000000 | F6: Económico: para pruebas, Medio: producción, Full: alta carga
B7: Almacenamiento en la nube 1TB | C7: 200000 | D7: 600000 | E7: 1500000 | F7: Económico: HDD, Medio: SSD, Full: SSD premium + replicación
B8: IP fija pública | C8: 50000 | D8: 200000 | E8: 500000 | F8: Económico: IP básica, Medio: IP dedicada, Full: IP+redundancia
B9: Balanceador de carga cloud | C9: 300000 | D9: 1000000 | E9: 2500000 | F9: Económico: básico, Medio: con SSL, Full: alta disponibilidad
B10: total Infraestructura cloud | C10: =SUM(C5:C9) -> 2350000 | D10: =SUM(D5:D9) -> 6300000 | E10: =SUM(E5:E9) -> 14500000
B11: Configuración Amazon Web Services (AWS)
B12: Configuración CI/CD (cloud) | C12: 400000 | D12: 1200000 | E12: 3000000 | F12: Económico: básico, Medio: completo, Full: con testing automático
B13: Docker / Kubernetes (cluster) | C13: 800000 | D13: 2500000 | E13: 6000000 | F13: Económico: Docker simple, Medio: K8s mediano, Full: clúster redundante
B14: Integración con sistemas locales | C14: 300000 | D14: 900000 | E14: 2500000 | F14: Económico: mínimamente, Medio: con scripts, Full: integración bidireccional completa
B15: total de configuracion | C15: =SUM(C12:C14) -> 1500000 | D15: =SUM(D12:D14) -> 4600000 | E15: =SUM(E12:E14) -> 11500000
B16: Costos mensuales de la nube
B17: Costo instancia cloud mensual | C17: 600000 | D17: 1500000 | E17: 3000000 | F17: Económico: VPS básico, Medio: alto rendimiento, Full: premium dedicado
B18: Costo base de datos cloud mensual | C18: 400000 | D18: 1200000 | E18: 3000000 | F18: Económico: DB básica, Medio: DB administrada, Full: DB HA
B19: Costo almacenamiento cloud mensualmente | C19: 100000 | D19: 400000 | E19: 1000000 | F19: Económico: Standard, Medio: SSD, Full: SSD+reducción latencia
B20: Transferencia de datos mensual | C20: 50000 | D20: 300000 | E20: 1000000 | F20: Económico: tráfico mínimo, Medio: estimado, Full: alto uso + redundancia
B21: total Costos mensuales de la nube | C21: =SUM(C17:C20) -> 1150000 | D21: =SUM(D17:D20) -> 3400000 | E21: =SUM(E17:E20) -> 8000000
